Workbook

Sheet Base_Altas_Recibidas
A1: BASE DE ALTAS RECIBIDAS · SOLICITUDES DE SEGUROS MASIVOS
A2: Datos simulados de 3 socios externos. A–I: datos recibidos · J–L: validación principal · M–O: auxiliares de RUT/auditoría · P–S: controles de completitud, catálogo, duplicidad y observaciones.
A4: ID_Solicitud | B4: Fecha_Recepcion | C4: Canal_Socio | D4: RUT_Asegurado | E4: Nombre_Asegurado | F4: Fecha_Nacimiento | G4: Edad_Calculada | H4: Plan_Solicitado | I4: Prima_Informada_CLP | J4: Prima_Oficial_PIMS | K4: Estado_Validacion | L4: Motivo_Rechazo | M4: RUT_Normalizado | N4: RUT_Valido | O4: Nro_Rechazo | P4: Control_Completitud | Q4: Plan_Catalogado | R4: Control_ID | S4: Errores_Adicionales
A5: SEC-1001 | B5: 46296 | C5: Socio_Retail_Gamma | D5: 23.449.342-6 | E5: Fernanda González Díaz | F5: 23571 | G5: =IF(OR(F5="",NOT(ISNUMBER(F5)),F5>TODAY()),"",DATEDIF(F5,TODAY(),"Y")) -> 62 | H5: Seguro Vida Senior | I5: 18990 | J5: =IFERROR(INDEX(Catalogo_Planes_PIMS!$C$5:$C$7,MATCH(H5,Catalogo_Planes_PIMS!$B$5:$B$7,0)),"") -> 18990 | K5: =IF(P5<>"OK","RECHAZADO_DATOS_INCOMPLETOS",IF(R5="DUPLICADO","RECHAZADO_ID_DUPLICADO",IF(Q5="NO","RECHAZADO_PLAN_NO_CATALOGADO",IF(OR(G5="",G5<IFERROR(INDEX(Catalogo_Planes_PIMS!$D$5:$D$7,MATCH(H5,Catalogo_Planes_PIMS!$B$5:$B$7,0)),18),G5>IFERROR(INDEX(Catalogo_Planes_PIMS!$E$5:$E$7,MATCH(H5,Catalogo_Planes_PIMS!$B$5:$B$7,0)),65)),"RECHAZADO_ELEGIBILIDAD",IF(N5="NO","RECHAZADO_RUT_INVALIDO",IF(OR(J5="",I5<>J5),"RECHAZADO_DESCALCE_PRIMA","APROBADO_CARGA_PIMS")))))) -> APROBADO_CARGA_PIMS | L5: =IF(K5="APROBADO_CARGA_PIMS","Sin observaciones",IF(K5="RECHAZADO_DATOS_INCOMPLETOS","Campos obligatorios incompletos o dato inválido",IF(K5="RECHAZADO_ID_DUPLICADO","Identificador de solicitud duplicado",IF(K5="RECHAZADO_PLAN_NO_CATALOGADO","Plan solicitado no existe en catálogo PIMS",IF(K5="RECHAZADO_ELEGIBILIDAD","Edad fuera del rango definido en catálogo",IF(K5="RECHAZADO_RUT_INVALIDO","RUT con formato o dígito verificador inválido","Prima informada no coincide con tarifa oficial PIMS")))))) -> Sin observaciones | M5: =SUBSTITUTE(SUBSTITUTE(SUBSTITUTE(UPPER(TRIM(D5)),".",""),"-","")," ","") -> 234493426 | N5: =IF(OR(D5="",ISERROR(FIND("-",TRIM(D5))),MID(TRIM(D5),LEN(TRIM(D5))-1,1)<>"-",LEN(M5)<8,LEN(M5)>9,NOT(ISNUMBER(--LEFT(M5,LEN(M5)-1))),NOT(OR(RIGHT(M5,1)="K",IFERROR(ISNUMBER(--RIGHT(M5,1)),FALSE())))),"NO",IF(RIGHT(M5,1)=MID("0K987654321",MOD(SUMPRODUCT(--MID(RIGHT("00000000"&LEFT(M5,LEN(M5)-1),8),{1,2,3,4,5,6,7,8},1),{3,2,7,6,5,4,3,2}),11)+1,1),"SI","NO")) -> SI | O5: =IF(LEFT(K5,9)="RECHAZADO",COUNTIF($K$5:K5,"RECHAZADO*"),"") | P5: =IF(OR(A5="",B5="",C5="",D5="",E5="",F5="",H5="",I5=""),"INCOMPLETO",IF(OR(NOT(ISNUMBER(B5)),NOT(ISNUMBER(F5)),F5>TODAY(),NOT(ISNUMBER(I5)),I5<0),"DATO_INVALIDO","OK")) -> OK | Q5: =IF(COUNTIF(Catalogo_Planes_PIMS!$B$5:$B$7,H5)=1,"SI","NO") -> SI | R5: =IF(A5="","",IF(COUNTIF($A$5:$A$104,A5)>1,"DUPLICADO","OK")) -> OK | S5: =IF(P5<>"OK","Revisar campos obligatorios, fechas y prima",IF(R5="DUPLICADO","ID_Solicitud duplicado",IF(Q5="NO","Plan no existe en catálogo",IF(AND(G5<>"",OR(G5<IFERROR(INDEX(Catalogo_Planes_PIMS!$D$5:$D$7,MATCH(H5,Catalogo_Planes_PIMS!$B$5:$B$7,0)),18),G5>IFERROR(INDEX(Catalogo_Planes_PIMS!$E$5:$E$7,MATCH(H5,Catalogo_Planes_PIMS!$B$5:$B$7,0)),65))),"Edad fuera de rango",IF(N5="NO","RUT inválido",IF(OR(J5="",I5<>J5),"Descalce de prima","Sin errores adicionales")))))) -> Sin errores adicionales
A6: SEC-1002 | B6: 46296 | C6: CallCenter_Beta | D6: 17.643.986-6 | E6: Camila González Araya | F6: 27636 | G6: =IF(OR(F6="",NOT(ISNUMBER(F6)),F6>TODAY()),"",DATEDIF(F6,TODAY(),"Y")) -> 51 | H6: Seguro Vida Senior | I6: 18990 | J6: =IFERROR(INDEX(Catalogo_Planes_PIMS!$C$5:$C$7,MATCH(H6,Catalogo_Planes_PIMS!$B$5:$B$7,0)),"") -> 18990 | K6: =IF(P6<>"OK","RECHAZADO_DATOS_INCOMPLETOS",IF(R6="DUPLICADO","RECHAZADO_ID_DUPLICADO",IF(Q6="NO","RECHAZADO_PLAN_NO_CATALOGADO",IF(OR(G6="",G6<IFERROR(INDEX(Catalogo_Planes_PIMS!$D$5:$D$7,MATCH(H6,Catalogo_Planes_PIMS!$B$5:$B$7,0)),18),G6>IFERROR(INDEX(Catalogo_Planes_PIMS!$E$5:$E$7,MATCH(H6,Catalogo_Planes_PIMS!$B$5:$B$7,0)),65)),"RECHAZADO_ELEGIBILIDAD",IF(N6="NO","RECHAZADO_RUT_INVALIDO",IF(OR(J6="",I6<>J6),"RECHAZADO_DESCALCE_PRIMA","APROBADO_CARGA_PIMS")))))) -> APROBADO_CARGA_PIMS | L6: =IF(K6="APROBADO_CARGA_PIMS","Sin observaciones",IF(K6="RECHAZADO_DATOS_INCOMPLETOS","Campos obligatorios incompletos o dato inválido",IF(K6="RECHAZADO_ID_DUPLICADO","Identificador de solicitud duplicado",IF(K6="RECHAZADO_PLAN_NO_CATALOGADO","Plan solicitado no existe en catálogo PIMS",IF(K6="RECHAZADO_ELEGIBILIDAD","Edad fuera del rango definido en catálogo",IF(K6="RECHAZADO_RUT_INVALIDO","RUT con formato o dígito verificador inválido","Prima informada no coincide con tarifa oficial PIMS")))))) -> Sin observaciones | M6: =SUBSTITUTE(SUBSTITUTE(SUBSTITUTE(UPPER(TRIM(D6)),".",""),"-","")," ","") -> 176439866 | N6: =IF(OR(D6="",ISERROR(FIND("-",TRIM(D6))),MID(TRIM(D6),LEN(TRIM(D6))-1,1)<>"-",LEN(M6)<8,LEN(M6)>9,NOT(ISNUMBER(--LEFT(M6,LEN(M6)-1))),NOT(OR(RIGHT(M6,1)="K",IFERROR(ISNUMBER(--RIGHT(M6,1)),FALSE())))),"NO",IF(RIGHT(M6,1)=MID("0K987654321",MOD(SUMPRODUCT(--MID(RIGHT("00000000"&LEFT(M6,LEN(M6)-1),8),{1,2,3,4,5,6,7,8},1),{3,2,7,6,5,4,3,2}),11)+1,1),"SI","NO")) -> SI | O6: =IF(LEFT(K6,9)="RECHAZADO",COUNTIF($K$5:K6,"RECHAZADO*"),"") | P6: =IF(OR(A6="",B6="",C6="",D6="",E6="",F6="",H6="",I6=""),"INCOMPLETO",IF(OR(NOT(ISNUMBER(B6)),NOT(ISNUMBER(F6)),F6>TODAY(),NOT(ISNUMBER(I6)),I6<0),"DATO_INVALIDO","OK")) -> OK | Q6: =IF(COUNTIF(Catalogo_Planes_PIMS!$B$5:$B$7,H6)=1,"SI","NO") -> SI | R6: =IF(A6="","",IF(COUNTIF($A$5:$A$104,A6)>1,"DUPLICADO","OK")) -> OK | S6: =IF(P6<>"OK","Revisar campos obligatorios, fechas y prima",IF(R6="DUPLICADO","ID_Solicitud duplicado",IF(Q6="NO","Plan no existe en catálogo",IF(AND(G6<>"",OR(G6<IFERROR(INDEX(Catalogo_Planes_PIMS!$D$5:$D$7,MATCH(H6,Catalogo_Planes_PIMS!$B$5:$B$7,0)),18),G6>IFERROR(INDEX(Catalogo_Planes_PIMS!$E$5:$E$7,MATCH(H6,Catalogo_Planes_PIMS!$B$5:$B$7,0)),65))),"Edad fuera de rango",IF(N6="NO","RUT inválido",IF(OR(J6="",I6<>J6),"Descalce de prima","Sin errores adicionales")))))) -> Sin errores adicionales
A7: SEC-1003 | B7: 46296 | C7: Socio_Retail_Gamma | D7: 21.104.204-4 | E7: Tomás Hernández Espinoza | F7: 26047 | G7: =IF(OR(F7="",NOT(ISNUMBER(F7)),F7>TODAY()),"",DATEDIF(F7,TODAY(),"Y")) -> 55 | H7: Seguro Vida Senior | I7: 17990 | J7: =IFERROR(INDEX(Catalogo_Planes_PIMS!$C$5:$C$7,MATCH(H7,Catalogo_Planes_PIMS!$B$5:$B$7,0)),"") -> 18990 | K7: =IF(P7<>"OK","RECHAZADO_DATOS_INCOMPLETOS",IF(R7="DUPLICADO","RECHAZADO_ID_DUPLICADO",IF(Q7="NO","RECHAZADO_PLAN_NO_CATALOGADO",IF(OR(G7="",G7<IFERROR(INDEX(Catalogo_Planes_PIMS!$D$5:$D$7,MATCH(H7,Catalogo_Planes_PIMS!$B$5:$B$7,0)),18),G7>IFERROR(INDEX(Catalogo_Planes_PIMS!$E$5:$E$7,MATCH(H7,Catalogo_Planes_PIMS!$B$5:$B$7,0)),65)),"RECHAZADO_ELEGIBILIDAD",IF(N7="NO","RECHAZADO_RUT_INVALIDO",IF(OR(J7="",I7<>J7),"RECHAZADO_DESCALCE_PRIMA","APROBADO_CARGA_PIMS")))))) -> RECHAZADO_DESCALCE_PRIMA | L7: =IF(K7="APROBADO_CARGA_PIMS","Sin observaciones",IF(K7="RECHAZADO_DATOS_INCOMPLETOS","Campos obligatorios incompletos o dato inválido",IF(K7="RECHAZADO_ID_DUPLICADO","Identificador de solicitud duplicado",IF(K7="RECHAZADO_PLAN_NO_CATALOGADO","Plan solicitado no existe en catálogo PIMS",IF(K7="RECHAZADO_ELEGIBILIDAD","Edad fuera del rango definido en catálogo",IF(K7="RECHAZADO_RUT_INVALIDO","RUT con formato o dígito verificador inválido","Prima informada no coincide con tarifa oficial PIMS")))))) -> Prima informada no coincide con tarifa oficial PIMS | M7: =SUBSTITUTE(SUBSTITUTE(SUBSTITUTE(UPPER(TRIM(D7)),".",""),"-","")," ","") -> 211042044 | N7: =IF(OR(D7="",ISERROR(FIND("-",TRIM(D7))),MID(TRIM(D7),LEN(TRIM(D7))-1,1)<>"-",LEN(M7)<8,LEN(M7)>9,NOT(ISNUMBER(--LEFT(M7,LEN(M7)-1))),NOT(OR(RIGHT(M7,1)="K",IFERROR(ISNUMBER(--RIGHT(M7,1)),FALSE())))),"NO",IF(RIGHT(M7,1)=MID("0K987654321",MOD(SUMPRODUCT(--MID(RIGHT("00000000"&LEFT(M7,LEN(M7)-1),8),{1,2,3,4,5,6,7,8},1),{3,2,7,6,5,4,3,2}),11)+1,1),"SI","NO")) -> SI | O7: =IF(LEFT(K7,9)="RECHAZADO",COUNTIF($K$5:K7,"RECHAZADO*"),"") -> 1 | P7: =IF(OR(A7="",B7="",C7="",D7="",E7="",F7="",H7="",I7=""),"INCOMPLETO",IF(OR(NOT(ISNUMBER(B7)),NOT(ISNUMBER(F7)),F7>TODAY(),NOT(ISNUMBER(I7)),I7<0),"DATO_INVALIDO","OK")) -> OK | Q7: =IF(COUNTIF(Catalogo_Planes_PIMS!$B$5:$B$7,H7)=1,"SI","NO") -> SI | R7: =IF(A7="","",IF(COUNTIF($A$5:$A$104,A7)>1,"DUPLICADO","OK")) -> OK | S7: =IF(P7<>"OK","Revisar campos obligatorios, fechas y prima",IF(R7="DUPLICADO","ID_Solicitud duplicado",IF(Q7="NO","Plan no existe en catálogo",IF(AND(G7<>"",OR(G7<IFERROR(INDEX(Catalogo_Planes_PIMS!$D$5:$D$7,MATCH(H7,Catalogo_Planes_PIMS!$B$5:$B$7,0)),18),G7>IFERROR(INDEX(Catalogo_Planes_PIMS!$E$5:$E$7,MATCH(H7,Catalogo_Planes_PIMS!$B$5:$B$7,0)),65))),"Edad fuera de rango",IF(N7="NO","RUT inválido",IF(OR(J7="",I7<>J7),"Descalce de prima","Sin errores adicionales")))))) -> Descalce de prima
A8: SEC-1004 | B8: 46296 | C8: CallCenter_Alpha | D8: 23.435.343-8 | E8: Rodrigo Morales Hernández | F8: 41454 | G8: =IF(OR(F8="",NOT(ISNUMBER(F8)),F8>TODAY()),"",DATEDIF(F8,TODAY(),"Y")) -> 13 | H8: Seguro Enseres Hogar | I8: 7990 | J8: =IFERROR(INDEX(Catalogo_Planes_PIMS!$C$5:$C$7,MATCH(H8,Catalogo_Planes_PIMS!$B$5:$B$7,0)),"") -> 7990 | K8: =IF(P8<>"OK","RECHAZADO_DATOS_INCOMPLETOS",IF(R8="DUPLICADO","RECHAZADO_ID_DUPLICADO",IF(Q8="NO","RECHAZADO_PLAN_NO_CATALOGADO",IF(OR(G8="",G8<IFERROR(INDEX(Catalogo_Planes_PIMS!$D$5:$D$7,MATCH(H8,Catalogo_Planes_PIMS!$B$5:$B$7,0)),18),G8>IFERROR(INDEX(Catalogo_Planes_PIMS!$E$5:$E$7,MATCH(H8,Catalogo_Planes_PIMS!$B$5:$B$7,0)),65)),"RECHAZADO_ELEGIBILIDAD",IF(N8="NO","RECHAZADO_RUT_INVALIDO",IF(OR(J8="",I8<>J8),"RECHAZADO_DESCALCE_PRIMA","APROBADO_CARGA_PIMS")))))) -> RECHAZADO_ELEGIBILIDAD | L8: =IF(K8="APROBADO_CARGA_PIMS","Sin observaciones",IF(K8="RECHAZADO_DATOS_INCOMPLETOS","Campos obligatorios incompletos o dato inválido",IF(K8="RECHAZADO_ID_DUPLICADO","Identificador de solicitud duplicado",IF(K8="RECHAZADO_PLAN_NO_CATALOGADO","Plan solicitado no existe en catálogo PIMS",IF(K8="RECHAZADO_ELEGIBILIDAD","Edad fuera del rango definido en catálogo",IF(K8="RECHAZADO_RUT_INVALIDO","RUT con formato o dígito verificador inválido","Prima informada no coincide con tarifa oficial PIMS")))))) -> Edad fuera del rango definido en catálogo | M8: =SUBSTITUTE(SUBSTITUTE(SUBSTITUTE(UPPER(TRIM(D8)),".",""),"-","")," ","") -> 234353438 | N8: =IF(OR(D8="",ISERROR(FIND("-",TRIM(D8))),MID(TRIM(D8),LEN(TRIM(D8))-1,1)<>"-",LEN(M8)<8,LEN(M8)>9,NOT(ISNUMBER(--LEFT(M8,LEN(M8)-1))),NOT(OR(RIGHT(M8,1)="K",IFERROR(ISNUMBER(--RIGHT(M8,1)),FALSE())))),"NO",IF(RIGHT(M8,1)=MID("0K987654321",MOD(SUMPRODUCT(--MID(RIGHT("00000000"&LEFT(M8,LEN(M8)-1),8),{1,2,3,4,5,6,7,8},1),{3,2,7,6,5,4,3,2}),11)+1,1),"SI","NO")) -> SI | O8: =IF(LEFT(K8,9)="RECHAZADO",COUNTIF($K$5:K8,"RECHAZADO*"),"") -> 2 | P8: =IF(OR(A8="",B8="",C8="",D8="",E8="",F8="",H8="",I8=""),"INCOMPLETO",IF(OR(NOT(ISNUMBER(B8)),NOT(ISNUMBER(F8)),F8>TODAY(),NOT(ISNUMBER(I8)),I8<0),"DATO_INVALIDO","OK")) -> OK | Q8: =IF(COUNTIF(Catalogo_Planes_PIMS!$B$5:$B$7,H8)=1,"SI","NO") -> SI | R8: =IF(A8="","",IF(COUNTIF($A$5:$A$104,A8)>1,"DUPLICADO","OK")) -> OK | S8: =IF(P8<>"OK","Revisar campos obligatorios, fechas y prima",IF(R8="DUPLICADO","ID_Solicitud duplicado",IF(Q8="NO","Plan no existe en catálogo",IF(AND(G8<>"",OR(G8<IFERROR(INDEX(Catalogo_Planes_PIMS!$D$5:$D$7,MATCH(H8,Catalogo_Planes_PIMS!$B$5:$B$7,0)),18),G8>IFERROR(INDEX(Catalogo_Planes_PIMS!$E$5:$E$7,MATCH(H8,Catalogo_Planes_PIMS!$B$5:$B$7,0)),65))),"Edad fuera de rango",IF(N8="NO","RUT inválido",IF(OR(J8="",I8<>J8),"Descalce de prima","Sin errores adicionales")))))) -> Edad fuera de rango
A9: SEC-1005 | B9: 46296 | C9: CallCenter_Alpha | D9: 24.366.151-K | E9: Constanza Castillo Soto | F9: 32372 | G9: =IF(OR(F9="",NOT(ISNUMBER(F9)),F9>TODAY()),"",DATEDIF(F9,TODAY(),"Y")) -> 38 | H9: Seguro Enseres Hogar | I9: 7990 | J9: =IFERROR(INDEX(Catalogo_Planes_PIMS!$C$5:$C$7,MATCH(H9,Catalogo_Planes_PIMS!$B$5:$B$7,0)),"") -> 7990 | K9: =IF(P9<>"OK","RECHAZADO_DATOS_INCOMPLETOS",IF(R9="DUPLICADO","RECHAZADO_ID_DUPLICADO",IF(Q9="NO","RECHAZADO_PLAN_NO_CATALOGADO",IF(OR(G9="",G9<IFERROR(INDEX(Catalogo_Planes_PIMS!$D$5:$D$7,MATCH(H9,Catalogo_Planes_PIMS!$B$5:$B$7,0)),18),G9>IFERROR(INDEX(Catalogo_Planes_PIMS!$E$5:$E$7,MATCH(H9,Catalogo_Planes_PIMS!$B$5:$B$7,0)),65)),"RECHAZADO_ELEGIBILIDAD",IF(N9="NO","RECHAZADO_RUT_INVALIDO",IF(OR(J9="",I9<>J9),"RECHAZADO_DESCALCE_PRIMA","APROBADO_CARGA_PIMS")))))) -> APROBADO_CARGA_PIMS | L9: =IF(K9="APROBADO_CARGA_PIMS","Sin observaciones",IF(K9="RECHAZADO_DATOS_INCOMPLETOS","Campos obligatorios incompletos o dato inválido",IF(K9="RECHAZADO_ID_DUPLICADO","Identificador de solicitud duplicado",IF(K9="RECHAZADO_PLAN_NO_CATALOGADO","Plan solicitado no existe en catálogo PIMS",IF(K9="RECHAZADO_ELEGIBILIDAD","Edad fuera del rango definido en catálogo",IF(K9="RECHAZADO_RUT_INVALIDO","RUT con formato o dígito verificador inválido","Prima informada no coincide con tarifa oficial PIMS")))))) -> Sin observaciones | M9: =SUBSTITUTE(SUBSTITUTE(SUBSTITUTE(UPPER(TRIM(D9)),".",""),"-","")," ","") -> 24366151K | N9: =IF(OR(D9="",ISERROR(FIND("-",TRIM(D9))),MID(TRIM(D9),LEN(TRIM(D9))-1,1)<>"-",LEN(M9)<8,LEN(M9)>9,NOT(ISNUMBER(--LEFT(M9,LEN(M9)-1))),NOT(OR(RIGHT(M9,1)="K",IFERROR(ISNUMBER(--RIGHT(M9,1)),FALSE())))),"NO",IF(RIGHT(M9,1)=MID("0K987654321",MOD(SUMPRODUCT(--MID(RIGHT("00000000"&LEFT(M9,LEN(M9)-1),8),{1,2,3,4,5,6,7,8},1),{3,2,7,6,5,4,3,2}),11)+1,1),"SI","NO")) -> SI | O9: =IF(LEFT(K9,9)="RECHAZADO",COUNTIF($K$5:K9,"RECHAZADO*"),"") | P9: =IF(OR(A9="",B9="",C9="",D9="",E9="",F9="",H9="",I9=""),"INCOMPLETO",IF(OR(NOT(ISNUMBER(B9)),NOT(ISNUMBER(F9)),F9>TODAY(),NOT(ISNUMBER(I9)),I9<0),"DATO_INVALIDO","OK")) -> OK | Q9: =IF(COUNTIF(Catalogo_Planes_PIMS!$B$5:$B$7,H9)=1,"SI","NO") -> SI | R9: =IF(A9="","",IF(COUNTIF($A$5:$A$104,A9)>1,"DUPLICADO","OK")) -> OK | S9: =IF(P9<>"OK","Revisar campos obligatorios, fechas y prima",IF(R9="DUPLICADO","ID_Solicitud duplicado",IF(Q9="NO","Plan no existe en catálogo",IF(AND(G9<>"",OR(G9<IFERROR(INDEX(Catalogo_Planes_PIMS!$D$5:$D$7,MATCH(H9,Catalogo_Planes_PIMS!$B$5:$B$7,0)),18),G9>IFERROR(INDEX(Catalogo_Planes_PIMS!$E$5:$E$7,MATCH(H9,Catalogo_Planes_PIMS!$B$5:$B$7,0)),65))),"Edad fuera de rango",IF(N9="NO","RUT inválido",IF(OR(J9="",I9<>J9),"Descalce de prima","Sin errores adicionales")))))) -> Sin errores adicionales
A10: SEC-1006 | B10: 46297 | C10: Socio_Retail_Gamma | D10: 21.160.592-8 | E10: Macarena Contreras Torres | F10: 25083 | G10: =IF(OR(F10="",NOT(ISNUMBER(F10)),F10>TODAY()),"",DATEDIF(F10,TODAY(),"Y")) -> 58 | H10: Seguro Salud Protegida | I10: 12990 | J10: =IFERROR(INDEX(Catalogo_Planes_PIMS!$C$5:$C$7,MATCH(H10,Catalogo_Planes_PIMS!$B$5:$B$7,0)),"") -> 12990 | K10: =IF(P10<>"OK","RECHAZADO_DATOS_INCOMPLETOS",IF(R10="DUPLICADO","RECHAZADO_ID_DUPLICADO",IF(Q10="NO","RECHAZADO_PLAN_NO_CATALOGADO",IF(OR(G10="",G10<IFERROR(INDEX(Catalogo_Planes_PIMS!$D$5:$D$7,MATCH(H10,Catalogo_Planes_PIMS!$B$5:$B$7,0)),18),G10>IFERROR(INDEX(Catalogo_Planes_PIMS!$E$5:$E$7,MATCH(H10,Catalogo_Planes_PIMS!$B$5:$B$7,0)),65)),"RECHAZADO_ELEGIBILIDAD",IF(N10="NO","RECHAZADO_RUT_INVALIDO",IF(OR(J10="",I10<>J10),"RECHAZADO_DESCALCE_PRIMA","APROBADO_CARGA_PIMS")))))) -> APROBADO_CARGA_PIMS | L10: =IF(K10="APROBADO_CARGA_PIMS","Sin observaciones",IF(K10="RECHAZADO_DATOS_INCOMPLETOS","Campos obligatorios incompletos o dato inválido",IF(K10="RECHAZADO_ID_DUPLICADO","Identificador de solicitud duplicado",IF(K10="RECHAZADO_PLAN_NO_CATALOGADO","Plan solicitado no existe en catálogo PIMS",IF(K10="RECHAZADO_ELEGIBILIDAD","Edad fuera del rango definido en catálogo",IF(K10="RECHAZADO_RUT_INVALIDO","RUT con formato o dígito verificador inválido","Prima informada no coincide con tarifa oficial PIMS")))))) -> Sin observaciones | M10: =SUBSTITUTE(SUBSTITUTE(SUBSTITUTE(UPPER(TRIM(D10)),".",""),"-","")," ","") -> 211605928 | N10: =IF(OR(D10="",ISERROR(FIND("-",TRIM(D10))),MID(TRIM(D10),LEN(TRIM(D10))-1,1)<>"-",LEN(M10)<8,LEN(M10)>9,NOT(ISNUMBER(--LEFT(M10,LEN(M10)-1))),NOT(OR(RIGHT(M10,1)="K",IFERROR(ISNUMBER(--RIGHT(M10,1)),FALSE())))),"NO",IF(RIGHT(M10,1)=MID("0K987654321",MOD(SUMPRODUCT(--MID(RIGHT("00000000"&LEFT(M10,LEN(M10)-1),8),{1,2,3,4,5,6,7,8},1),{3,2,7,6,5,4,3,2}),11)+1,1),"SI","NO")) -> SI | O10: =IF(LEFT(K10,9)="RECHAZADO",COUNTIF($K$5:K10,"RECHAZADO*"),"") | P10: =IF(OR(A10="",B10="",C10="",D10="",E10="",F10="",H10="",I10=""),"INCOMPLETO",IF(OR(NOT(ISNUMBER(B10)),NOT(ISNUMBER(F10)),F10>TODAY(),NOT(ISNUMBER(I10)),I10<0),"DATO_INVALIDO","OK")) -> OK | Q10: =IF(COUNTIF(Catalogo_Planes_PIMS!$B$5:$B$7,H10)=1,"SI","NO") -> SI | R10: =IF(A10="","",IF(COUNTIF($A$5:$A$104,A10)>1,"DUPLICADO","OK")) -> OK | S10: =IF(P10<>"OK","Revisar campos obligatorios, fechas y prima",IF(R10="DUPLICADO","ID_Solicitud duplicado",IF(Q10="NO","Plan no existe en catálogo",IF(AND(G10<>"",OR(G10<IFERROR(INDEX(Catalogo_Planes_PIMS!$D$5:$D$7,MATCH(H10,Catalogo_Planes_PIMS!$B$5:$B$7,0)),18),G10>IFERROR(INDEX(Catalogo_Planes_PIMS!$E$5:$E$7,MATCH(H10,Catalogo_Planes_PIMS!$B$5:$B$7,0)),65))),"Edad fuera de rango",IF(N10="NO","RUT inválido",IF(OR(J10="",I10<>J10),"Descalce de prima","Sin errores adicionales")))))) -> Sin errores adicionales
A11: SEC-1007 | B11: 46297 | C11: CallCenter_Alpha | D11: 23.781.720-6 | E11: Paula Pérez Soto | F11: 37086 | G11: =IF(OR(F11="",NOT(ISNUMBER(F11)),F11>TODAY()),"",DATEDIF(F11,TODAY(),"Y")) -> 25 | H11: Seguro Enseres Hogar | I11: 7990 | J11: =IFERROR(INDEX(Catalogo_Planes_PIMS!$C$5:$C$7,MATCH(H11,Catalogo_Planes_PIMS!$B$5:$B$7,0)),"") -> 7990 | K11: =IF(P11<>"OK","RECHAZADO_DATOS_INCOMPLETOS",IF(R11="DUPLICADO","RECHAZADO_ID_DUPLICADO",IF(Q11="NO","RECHAZADO_PLAN_NO_CATALOGADO",IF(OR(G11="",G11<IFERROR(INDEX(Catalogo_Planes_PIMS!$D$5:$D$7,MATCH(H11,Catalogo_Planes_PIMS!$B$5:$B$7,0)),18),G11>IFERROR(INDEX(Catalogo_Planes_PIMS!$E$5:$E$7,MATCH(H11,Catalogo_Planes_PIMS!$B$5:$B$7,0)),65)),"RECHAZADO_ELEGIBILIDAD",IF(N11="NO","RECHAZADO_RUT_INVALIDO",IF(OR(J11="",I11<>J11),"RECHAZADO_DESCALCE_PRIMA","APROBADO_CARGA_PIMS")))))) -> APROBADO_CARGA_PIMS | L11: =IF(K11="APROBADO_CARGA_PIMS","Sin observaciones",IF(K11="RECHAZADO_DATOS_INCOMPLETOS","Campos obligatorios incompletos o dato inválido",IF(K11="RECHAZADO_ID_DUPLICADO","Identificador de solicitud duplicado",IF(K11="RECHAZADO_PLAN_NO_CATALOGADO","Plan solicitado no existe en catálogo PIMS",IF(K11="RECHAZADO_ELEGIBILIDAD","Edad fuera del rango definido en catálogo",IF(K11="RECHAZADO_RUT_INVALIDO","RUT con formato o dígito verificador inválido","Prima informada no coincide con tarifa oficial PIMS")))))) -> Sin observaciones | M11: =SUBSTITUTE(SUBSTITUTE(SUBSTITUTE(UPPER(TRIM(D11)),".",""),"-","")," ","") -> 237817206 | N11: =IF(OR(D11="",ISERROR(FIND("-",TRIM(D11))),MID(TRIM(D11),LEN(TRIM(D11))-1,1)<>"-",LEN(M11)<8,LEN(M11)>9,NOT(ISNUMBER(--LEFT(M11,LEN(M11)-1))),NOT(OR(RIGHT(M11,1)="K",IFERROR(ISNUMBER(--RIGHT(M11,1)),FALSE())))),"NO",IF(RIGHT(M11,1)=MID("0K987654321",MOD(SUMPRODUCT(--MID(RIGHT("00000000"&LEFT(M11,LEN(M11)-1),8),{1,2,3,4,5,6,7,8},1),{3,2,7,6,5,4,3,2}),11)+1,1),"SI","NO")) -> SI | O11: =IF(LEFT(K11,9)="RECHAZADO",COUNTIF($K$5:K11,"RECHAZADO*"),"") | P11: =IF(OR(A11="",B11="",C11="",D11="",E11="",F11="",H11="",I11=""),"INCOMPLETO",IF(OR(NOT(ISNUMBER(B11)),NOT(ISNUMBER(F11)),F11>TODAY(),NOT(ISNUMBER(I11)),I11<0),"DATO_INVALIDO","OK")) -> OK | Q11: =IF(COUNTIF(Catalogo_Planes_PIMS!$B$5:$B$7,H11)=1,"SI","NO") -> SI | R11: =IF(A11="","",IF(COUNTIF($A$5:$A$104,A11)>1,"DUPLICADO","OK")) -> OK | S11: =IF(P11<>"OK","Revisar campos obligatorios, fechas y prima",IF(R11="DUPLICADO","ID_Solicitud duplicado",IF(Q11="NO","Plan no existe en catálogo",IF(AND(G11<>"",OR(G11<IFERROR(INDEX(Catalogo_Planes_PIMS!$D$5:$D$7,MATCH(H11,Catalogo_Planes_PIMS!$B$5:$B$7,0)),18),G11>IFERROR(INDEX(Catalogo_Planes_PIMS!$E$5:$E$7,MATCH(H11,Catalogo_Planes_PIMS!$B$5:$B$7,0)),65))),"Edad fuera de rango",IF(N11="NO","RUT inválido",IF(OR(J11="",I11<>J11),"Descalce de prima","Sin errores adicionales")))))) -> Sin errores adicionales
A12: SEC-1008 | B12: 46297 | C12: CallCenter_Beta | D12: 15.153.880-0 | E12: Valentina López Sepúlveda | F12: 33303 | G12: =IF(OR(F12="",NOT(ISNUMBER(F12)),F12>TODAY()),"",DATEDIF(F12,TODAY(),"Y")) -> 35 | H12: Seguro Enseres Hogar | I12: 9490 | J12: =IFERROR(INDEX(Catalogo_Planes_PIMS!$C$5:$C$7,MATCH(H12,Catalogo_Planes_PIMS!$B$5:$B$7,0)),"") -> 7990 | K12: =IF(P12<>"OK","RECHAZADO_DATOS_INCOMPLETOS",IF(R12="DUPLICADO","RECHAZADO_ID_DUPLICADO",IF(Q12="NO","RECHAZADO_PLAN_NO_CATALOGADO",IF(OR(G12="",G12<IFERROR(INDEX(Catalogo_Planes_PIMS!$D$5:$D$7,MATCH(H12,Catalogo_Planes_PIMS!$B$5:$B$7,0)),18),G12>IFERROR(INDEX(Catalogo_Planes_PIMS!$E$5:$E$7,MATCH(H12,Catalogo_Planes_PIMS!$B$5:$B$7,0)),65)),"RECHAZADO_ELEGIBILIDAD",IF(N12="NO","RECHAZADO_RUT_INVALIDO",IF(OR(J12="",I12<>J12),"RECHAZADO_DESCALCE_PRIMA","APROBADO_CARGA_PIMS")))))) -> RECHAZADO_DESCALCE_PRIMA | L12: =IF(K12="APROBADO_CARGA_PIMS","Sin observaciones",IF(K12="RECHAZADO_DATOS_INCOMPLETOS","Campos obligatorios incompletos o dato inválido",IF(K12="RECHAZADO_ID_DUPLICADO","Identificador de solicitud duplicado",IF(K12="RECHAZADO_PLAN_NO_CATALOGADO","Plan solicitado no existe en catálogo PIMS",IF(K12="RECHAZADO_ELEGIBILIDAD","Edad fuera del rango definido en catálogo",IF(K12="RECHAZADO_RUT_INVALIDO","RUT con formato o dígito verificador inválido","Prima informada no coincide con tarifa oficial PIMS")))))) -> Prima informada no coincide con tarifa oficial PIMS | M12: =SUBSTITUTE(SUBSTITUTE(SUBSTITUTE(UPPER(TRIM(D12)),".",""),"-","")," ","") -> 151538800 | N12: =IF(OR(D12="",ISERROR(FIND("-",TRIM(D12))),MID(TRIM(D12),LEN(TRIM(D12))-1,1)<>"-",LEN(M12)<8,LEN(M12)>9,NOT(ISNUMBER(--LEFT(M12,LEN(M12)-1))),NOT(OR(RIGHT(M12,1)="K",IFERROR(ISNUMBER(--RIGHT(M12,1)),FALSE())))),"NO",IF(RIGHT(M12,1)=MID("0K987654321",MOD(SUMPRODUCT(--MID(RIGHT("00000000"&LEFT(M12,LEN(M12)-1),8),{1,2,3,4,5,6,7,8},1),{3,2,7,6,5,4,3,2}),11)+1,1),"SI","NO")) -> SI | O12: =IF(LEFT(K12,9)="RECHAZADO",COUNTIF($K$5:K12,"RECHAZADO*"),"") -> 3 | P12: =IF(OR(A12="",B12="",C12="",D12="",E12="",F12="",H12="",I12=""),"INCOMPLETO",IF(OR(NOT(ISNUMBER(B12)),NOT(ISNUMBER(F12)),F12>TODAY(),NOT(ISNUMBER(I12)),I12<0),"DATO_INVALIDO","OK")) -> OK | Q12: =IF(COUNTIF(Catalogo_Planes_PIMS!$B$5:$B$7,H12)=1,"SI","NO") -> SI | R12: =IF(A12="","",IF(COUNTIF($A$5:$A$104,A12)>1,"DUPLICADO","OK")) -> OK | S12: =IF(P12<>"OK","Revisar campos obligatorios, fechas y prima",IF(R12="DUPLICADO","ID_Solicitud duplicado",IF(Q12="NO","Plan no existe en catálogo",IF(AND(G12<>"",OR(G12<IFERROR(INDEX(Catalogo_Planes_PIMS!$D$5:$D$7,MATCH(H12,Catalogo_Planes_PIMS!$B$5:$B$7,0)),18),G12>IFERROR(INDEX(Catalogo_Planes_PIMS!$E$5:$E$7,MATCH(H12,Catalogo_Planes_PIMS!$B$5:$B$7,0)),65))),"Edad fuera de rango",IF(N12="NO","RUT inválido",IF(OR(J12="",I12<>J12),"Descalce de prima","Sin errores adicionales")))))) -> Descalce de prima
A13: SEC-1009 | B13: 46297 | C13: CallCenter_Beta | D13: 14.839.703-1 | E13: Ignacio Sepúlveda Hernández | F13: 29398 | G13: =IF(OR(F13="",NOT(ISNUMBER(F13)),F13>TODAY()),"",DATEDIF(F13,TODAY(),"Y")) -> 46 | H13: Seguro Salud Protegida | I13: 14490 | J13: =IFERROR(INDEX(Catalogo_Planes_PIMS!$C$5:$C$7,MATCH(H13,Catalogo_Planes_PIMS!$B$5:$B$7,0)),"") -> 12990 | K13: =IF(P13<>"OK","RECHAZADO_DATOS_INCOMPLETOS",IF(R13="DUPLICADO","RECHAZADO_ID_DUPLICADO",IF(Q13="NO","RECHAZADO_PLAN_NO_CATALOGADO",IF(OR(G13="",G13<IFERROR(INDEX(Catalogo_Planes_PIMS!$D$5:$D$7,MATCH(H13,Catalogo_Planes_PIMS!$B$5:$B$7,0)),18),G13>IFERROR(INDEX(Catalogo_Planes_PIMS!$E$5:$E$7,MATCH(H13,Catalogo_Planes_PIMS!$B$5:$B$7,0)),65)),"RECHAZADO_ELEGIBILIDAD",IF(N13="NO","RECHAZADO_RUT_INVALIDO",IF(OR(J13="",I13<>J13),"RECHAZADO_DESCALCE_PRIMA","APROBADO_CARGA_PIMS")))))) -> RECHAZADO_DESCALCE_PRIMA | L13: =IF(K13="APROBADO_CARGA_PIMS","Sin observaciones",IF(K13="RECHAZADO_DATOS_INCOMPLETOS","Campos obligatorios incompletos o dato inválido",IF(K13="RECHAZADO_ID_DUPLICADO","Identificador de solicitud duplicado",IF(K13="RECHAZADO_PLAN_NO_CATALOGADO","Plan solicitado no existe en catálogo PIMS",IF(K13="RECHAZADO_ELEGIBILIDAD","Edad fuera del rango definido en catálogo",IF(K13="RECHAZADO_RUT_INVALIDO","RUT con formato o dígito verificador inválido","Prima informada no coincide con tarifa oficial PIMS")))))) -> Prima informada no coincide con tarifa oficial PIMS | M13: =SUBSTITUTE(SUBSTITUTE(SUBSTITUTE(UPPER(TRIM(D13)),".",""),"-","")," ","") -> 148397031 | N13: =IF(OR(D13="",ISERROR(FIND("-",TRIM(D13))),MID(TRIM(D13),LEN(TRIM(D13))-1,1)<>"-",LEN(M13)<8,LEN(M13)>9,NOT(ISNUMBER(--LEFT(M13,LEN(M13)-1))),NOT(OR(RIGHT(M13,1)="K",IFERROR(ISNUMBER(--RIGHT(M13,1)),FALSE())))),"NO",IF(RIGHT(M13,1)=MID("0K987654321",MOD(SUMPRODUCT(--MID(RIGHT("00000000"&LEFT(M13,LEN(M13)-1),8),{1,2,3,4,5,6,7,8},1),{3,2,7,6,5,4,3,2}),11)+1,1),"SI","NO")) -> SI | O13: =IF(LEFT(K13,9)="RECHAZADO",COUNTIF($K$5:K13,"RECHAZADO*"),"") -> 4 | P13: =IF(OR(A13="",B13="",C13="",D13="",E13="",F13="",H13="",I13=""),"INCOMPLETO",IF(OR(NOT(ISNUMBER(B13)),NOT(ISNUMBER(F13)),F13>TODAY(),NOT(ISNUMBER(I13)),I13<0),"DATO_INVALIDO","OK")) -> OK | Q13: =IF(COUNTIF(Catalogo_Planes_PIMS!$B$5:$B$7,H13)=1,"SI","NO") -> SI | R13: =IF(A13="","",IF(COUNTIF($A$5:$A$104,A13)>1,"DUPLICADO","OK")) -> OK | S13: =IF(P13<>"OK","Revisar campos obligatorios, fechas y prima",IF(R13="DUPLICADO","ID_Solicitud duplicado",IF(Q13="NO","Plan no existe en catálogo",IF(AND(G13<>"",OR(G13<IFERROR(INDEX(Catalogo_Planes_PIMS!$D$5:$D$7,MATCH(H13,Catalogo_Planes_PIMS!$B$5:$B$7,0)),18),G13>IFERROR(INDEX(Catalogo_Planes_PIMS!$E$5:$E$7,MATCH(H13,Catalogo_Planes_PIMS!$B$5:$B$7,0)),65))),"Edad fuera de rango",IF(N13="NO","RUT inválido",IF(OR(J13="",I13<>J13),"Descalce de prima","Sin errores adicionales")))))) -> Descalce de prima
A14: SEC-1010 | B14: 46297 | C14: CallCenter_Beta | D14: 22.175.007-1 | E14: Paula Araya Martínez | F14: 29952 | G14: =IF(OR(F14="",NOT(ISNUMBER(F14)),F14>TODAY()),"",DATEDIF(F14,TODAY(),"Y")) -> 44 | H14: Seguro Salud Protegida | I14: 12990 | J14: =IFERROR(INDEX(Catalogo_Planes_PIMS!$C$5:$C$7,MATCH(H14,Catalogo_Planes_PIMS!$B$5:$B$7,0)),"") -> 12990 | K14: =IF(P14<>"OK","RECHAZADO_DATOS_INCOMPLETOS",IF(R14="DUPLICADO","RECHAZADO_ID_DUPLICADO",IF(Q14="NO","RECHAZADO_PLAN_NO_CATALOGADO",IF(OR(G14="",G14<IFERROR(INDEX(Catalogo_Planes_PIMS!$D$5:$D$7,MATCH(H14,Catalogo_Planes_PIMS!$B$5:$B$7,0)),18),G14>IFERROR(INDEX(Catalogo_Planes_PIMS!$E$5:$E$7,MATCH(H14,Catalogo_Planes_PIMS!$B$5:$B$7,0)),65)),"RECHAZADO_ELEGIBILIDAD",IF(N14="NO","RECHAZADO_RUT_INVALIDO",IF(OR(J14="",I14<>J14),"RECHAZADO_DESCALCE_PRIMA","APROBADO_CARGA_PIMS")))))) -> APROBADO_CARGA_PIMS | L14: =IF(K14="APROBADO_CARGA_PIMS","Sin observaciones",IF(K14="RECHAZADO_DATOS_INCOMPLETOS","Campos obligatorios incompletos o dato inválido",IF(K14="RECHAZADO_ID_DUPLICADO","Identificador de solicitud duplicado",IF(K14="RECHAZADO_PLAN_NO_CATALOGADO","Plan solicitado no existe en catálogo PIMS",IF(K14="RECHAZADO_ELEGIBILIDAD","Edad fuera del rango definido en catálogo",IF(K14="RECHAZADO_RUT_INVALIDO","RUT con formato o dígito verificador inválido","Prima informada no coincide con tarifa oficial PIMS")))))) -> Sin observaciones | M14: =SUBSTITUTE(SUBSTITUTE(SUBSTITUTE(UPPER(TRIM(D14)),".",""),"-","")," ","") -> 221750071 | N14: =IF(OR(D14="",ISERROR(FIND("-",TRIM(D14))),MID(TRIM(D14),LEN(TRIM(D14))-1,1)<>"-",LEN(M14)<8,LEN(M14)>9,NOT(ISNUMBER(--LEFT(M14,LEN(M14)-1))),NOT(OR(RIGHT(M14,1)="K",IFERROR(ISNUMBER(--RIGHT(M14,1)),FALSE())))),"NO",IF(RIGHT(M14,1)=MID("0K987654321",MOD(SUMPRODUCT(--MID(RIGHT("00000000"&LEFT(M14,LEN(M14)-1),8),{1,2,3,4,5,6,7,8},1),{3,2,7,6,5,4,3,2}),11)+1,1),"SI","NO")) -> SI | O14: =IF(LEFT(K14,9)="RECHAZADO",COUNTIF($K$5:K14,"RECHAZADO*"),"") | P14: =IF(OR(A14="",B14="",C14="",D14="",E14="",F14="",H14="",I14=""),"INCOMPLETO",IF(OR(NOT(ISNUMBER(B14)),NOT(ISNUMBER(F14)),F14>TODAY(),NOT(ISNUMBER(I14)),I14<0),"DATO_INVALIDO","OK")) -> OK | Q14: =IF(COUNTIF(Catalogo_Planes_PIMS!$B$5:$B$7,H14)=1,"SI","NO") -> SI | R14: =IF(A14="","",IF(COUNTIF($A$5:$A$104,A14)>1,"DUPLICADO","OK")) -> OK | S14: =IF(P14<>"OK","Revisar campos obligatorios, fechas y prima",IF(R14="DUPLICADO","ID_Solicitud duplicado",IF(Q14="NO","Plan no existe en catálogo",IF(AND(G14<>"",OR(G14<IFERROR(INDEX(Catalogo_Planes_PIMS!$D$5:$D$7,MATCH(H14,Catalogo_Planes_PIMS!$B$5:$B$7,0)),18),G14>IFERROR(INDEX(Catalogo_Planes_PIMS!$E$5:$E$7,MATCH(H14,Catalogo_Planes_PIMS!$B$5:$B$7,0)),65))),"Edad fuera de rango",IF(N14="NO","RUT inválido",IF(OR(J14="",I14<>J14),"Descalce de prima","Sin errores adicionales")))))) -> Sin errores adicionales
A15: SEC-1011 | B15: 46297 | C15: Socio_Retail_Gamma | D15: 6.164.612-7 | E15: Macarena Morales Fuentes | F15: 32654 | G15: =IF(OR(F15="",NOT(ISNUMBER(F15)),F15>TODAY()),"",DATEDIF(F15,TODAY(),"Y")) -> 37 | H15: Seguro Salud Protegida | I15: 12990 | J15: =IFERROR(INDEX(Catalogo_Planes_PIMS!$C$5:$C$7,MATCH(H15,Catalogo_Planes_PIMS!$B$5:$B$7,0)),"") -> 12990 | K15: =IF(P15<>"OK","RECHAZADO_DATOS_INCOMPLETOS",IF(R15="DUPLICADO","RECHAZADO_ID_DUPLICADO",IF(Q15="NO","RECHAZADO_PLAN_NO_CATALOGADO",IF(OR(G15="",G15<IFERROR(INDEX(Catalogo_Planes_PIMS!$D$5:$D$7,MATCH(H15,Catalogo_Planes_PIMS!$B$5:$B$7,0)),18),G15>IFERROR(INDEX(Catalogo_Planes_PIMS!$E$5:$E$7,MATCH(H15,Catalogo_Planes_PIMS!$B$5:$B$7,0)),65)),"RECHAZADO_ELEGIBILIDAD",IF(N15="NO","RECHAZADO_RUT_INVALIDO",IF(OR(J15="",I15<>J15),"RECHAZADO_DESCALCE_PRIMA","APROBADO_CARGA_PIMS")))))) -> RECHAZADO_RUT_INVALIDO | L15: =IF(K15="APROBADO_CARGA_PIMS","Sin observaciones",IF(K15="RECHAZADO_DATOS_INCOMPLETOS","Campos obligatorios incompletos o dato inválido",IF(K15="RECHAZADO_ID_DUPLICADO","Identificador de solicitud duplicado",IF(K15="RECHAZADO_PLAN_NO_CATALOGADO","Plan solicitado no existe en catálogo PIMS",IF(K15="RECHAZADO_ELEGIBILIDAD","Edad fuera del rango definido en catálogo",IF(K15="RECHAZADO_RUT_INVALIDO","RUT con formato o dígito verificador inválido","Prima informada no coincide con tarifa oficial PIMS")))))) -> RUT con formato o dígito verificador inválido | M15: =SUBSTITUTE(SUBSTITUTE(SUBSTITUTE(UPPER(TRIM(D15)),".",""),"-","")," ","") -> 61646127 | N15: =IF(OR(D15="",ISERROR(FIND("-",TRIM(D15))),MID(TRIM(D15),LEN(TRIM(D15))-1,1)<>"-",LEN(M15)<8,LEN(M15)>9,NOT(ISNUMBER(--LEFT(M15,LEN(M15)-1))),NOT(OR(RIGHT(M15,1)="K",IFERROR(ISNUMBER(--RIGHT(M15,1)),FALSE())))),"NO",IF(RIGHT(M15,1)=MID("0K987654321",MOD(SUMPRODUCT(--MID(RIGHT("00000000"&LEFT(M15,LEN(M15)-1),8),{1,2,3,4,5,6,7,8},1),{3,2,7,6,5,4,3,2}),11)+1,1),"SI","NO")) -> NO | O15: =IF(LEFT(K15,9)="RECHAZADO",COUNTIF($K$5:K15,"RECHAZADO*"),"") -> 5 | P15: =IF(OR(A15="",B15="",C15="",D15="",E15="",F15="",H15="",I15=""),"INCOMPLETO",IF(OR(NOT(ISNUMBER(B15)),NOT(ISNUMBER(F15)),F15>TODAY(),NOT(ISNUMBER(I15)),I15<0),"DATO_INVALIDO","OK")) -> OK | Q15: =IF(COUNTIF(Catalogo_Planes_PIMS!$B$5:$B$7,H15)=1,"SI","NO") -> SI | R15: =IF(A15="","",IF(COUNTIF($A$5:$A$104,A15)>1,"DUPLICADO","OK")) -> OK | S15: =IF(P15<>"OK","Revisar campos obligatorios, fechas y prima",IF(R15="DUPLICADO","ID_Solicitud duplicado",IF(Q15="NO","Plan no existe en catálogo",IF(AND(G15<>"",OR(G15<IFERROR(INDEX(Catalogo_Planes_PIMS!$D$5:$D$7,MATCH(H15,Catalogo_Planes_PIMS!$B$5:$B$7,0)),18),G15>IFERROR(INDEX(Catalogo_Planes_PIMS!$E$5:$E$7,MATCH(H15,Catalogo_Planes_PIMS!$B$5:$B$7,0)),65))),"Edad fuera de rango",IF(N15="NO","RUT inválido",IF(OR(J15="",I15<>J15),"Descalce de prima","Sin errores adicionales")))))) -> RUT inválido
A16: SEC-1012 | B16: 46297 | C16: Socio_Retail_Gamma | D16: 17.809.487-4 | E16: Cristóbal Flores Tapia | F16: 33489 | G16: =IF(OR(F16="",NOT(ISNUMBER(F16)),F16>TODAY()),"",DATEDIF(F16,TODAY(),"Y")) -> 35 | H16: Seguro Enseres Hogar | I16: 7990 | J16: =IFERROR(INDEX(Catalogo_Planes_PIMS!$C$5:$C$7,MATCH(H16,Catalogo_Planes_PIMS!$B$5:$B$7,0)),"") -> 7990 | K16: =IF(P16<>"OK","RECHAZADO_DATOS_INCOMPLETOS",IF(R16="DUPLICADO","RECHAZADO_ID_DUPLICADO",IF(Q16="NO","RECHAZADO_PLAN_NO_CATALOGADO",IF(OR(G16="",G16<IFERROR(INDEX(Catalogo_Planes_PIMS!$D$5:$D$7,MATCH(H16,Catalogo_Planes_PIMS!$B$5:$B$7,0)),18),G16>IFERROR(INDEX(Catalogo_Planes_PIMS!$E$5:$E$7,MATCH(H16,Catalogo_Planes_PIMS!$B$5:$B$7,0)),65)),"RECHAZADO_ELEGIBILIDAD",IF(N16="NO","RECHAZADO_RUT_INVALIDO",IF(OR(J16="",I16<>J16),"RECHAZADO_DESCALCE_PRIMA","APROBADO_CARGA_PIMS")))))) -> APROBADO_CARGA_PIMS | L16: =IF(K16="APROBADO_CARGA_PIMS","Sin observaciones",IF(K16="RECHAZADO_DATOS_INCOMPLETOS","Campos obligatorios incompletos o dato inválido",IF(K16="RECHAZADO_ID_DUPLICADO","Identificador de solicitud duplicado",IF(K16="RECHAZADO_PLAN_NO_CATALOGADO","Plan solicitado no existe en catálogo PIMS",IF(K16="RECHAZADO_ELEGIBILIDAD","Edad fuera del rango definido en catálogo",IF(K16="RECHAZADO_RUT_INVALIDO","RUT con formato o dígito verificador inválido","Prima informada no coincide con tarifa oficial PIMS")))))) -> Sin observaciones | M16: =SUBSTITUTE(SUBSTITUTE(SUBSTITUTE(UPPER(TRIM(D16)),".",""),"-","")," ","") -> 178094874 | N16: =IF(OR(D16="",ISERROR(FIND("-",TRIM(D16))),MID(TRIM(D16),LEN(TRIM(D16))-1,1)<>"-",LEN(M16)<8,LEN(M16)>9,NOT(ISNUMBER(--LEFT(M16,LEN(M16)-1))),NOT(OR(RIGHT(M16,1)="K",IFERROR(ISNUMBER(--RIGHT(M16,1)),FALSE())))),"NO",IF(RIGHT(M16,1)=MID("0K987654321",MOD(SUMPRODUCT(--MID(RIGHT("00000000"&LEFT(M16,LEN(M16)-1),8),{1,2,3,4,5,6,7,8},1),{3,2,7,6,5,4,3,2}),11)+1,1),"SI","NO")) -> SI | O16: =IF(LEFT(K16,9)="RECHAZADO",COUNTIF($K$5:K16,"RECHAZADO*"),"") | P16: =IF(OR(A16="",B16="",C16="",D16="",E16="",F16="",H16="",I16=""),"INCOMPLETO",IF(OR(NOT(ISNUMBER(B16)),NOT(ISNUMBER(F16)),F16>TODAY(),NOT(ISNUMBER(I16)),I16<0),"DATO_INVALIDO","OK")) -> OK | Q16: =IF(COUNTIF(Catalogo_Planes_PIMS!$B$5:$B$7,H16)=1,"SI","NO") -> SI | R16: =IF(A16="","",IF(COUNTIF($A$5:$A$104,A16)>1,"DUPLICADO","OK")) -> OK | S16: =IF(P16<>"OK","Revisar campos obligatorios, fechas y prima",IF(R16="DUPLICADO","ID_Solicitud duplicado",IF(Q16="NO","Plan no existe en catálogo",IF(AND(G16<>"",OR(G16<IFERROR(INDEX(Catalogo_Planes_PIMS!$D$5:$D$7,MATCH(H16,Catalogo_Planes_PIMS!$B$5:$B$7,0)),18),G16>IFERROR(INDEX(Catalogo_Planes_PIMS!$E$5:$E$7,MATCH(H16,Catalogo_Planes_PIMS!$B$5:$B$7,0)),65))),"Edad fuera de rango",IF(N16="NO","RUT inválido",IF(OR(J16="",I16<>J16),"Descalce de prima","Sin errores adicionales")))))) -> Sin errores adicionales
... A104: SEC-1100 | B104: 46307 | C104: CallCenter_Beta | D104: 24.369.498-1 | E104: Carolina Flores Silva | F104: 21372 | G104: =IF(OR(F104="",NOT(ISNUMBER(F104)),F104>TODAY()),"",DATEDIF(F104,TODAY(),"Y")) -> 68 | H104: Seguro Vida Senior | I104: 18990 | J104: =IFERROR(INDEX(Catalogo_Planes_PIMS!$C$5:$C$7,MATCH(H104,Catalogo_Planes_PIMS!$B$5:$B$7,0)),"") -> 18990 | K104: =IF(P104<>"OK","RECHAZADO_DATOS_INCOMPLETOS",IF(R104="DUPLICADO","RECHAZADO_ID_DUPLICADO",IF(Q104="NO","RECHAZADO_PLAN_NO_CATALOGADO",IF(OR(G104="",G104<IFERROR(INDEX(Catalogo_Planes_PIMS!$D$5:$D$7,MATCH(H104,Catalogo_Planes_PIMS!$B$5:$B$7,0)),18),G104>IFERROR(INDEX(Catalogo_Planes_PIMS!$E$5:$E$7,MATCH(H104,Catalogo_Planes_PIMS!$B$5:$B$7,0)),65)),"RECHAZADO_ELEGIBILIDAD",IF(N104="NO","RECHAZADO_RUT_INVALIDO",IF(OR(J104="",I104<>J104),"RECHAZADO_DESCALCE_PRIMA","APROBADO_CARGA_PIMS")))))) -> RECHAZADO_ELEGIBILIDAD | L104: =IF(K104="APROBADO_CARGA_PIMS","Sin observaciones",IF(K104="RECHAZADO_DATOS_INCOMPLETOS","Campos obligatorios incompletos o dato inválido",IF(K104="RECHAZADO_ID_DUPLICADO","Identificador de solicitud duplicado",IF(K104="RECHAZADO_PLAN_NO_CATALOGADO","Plan solicitado no existe en catálogo PIMS",IF(K104="RECHAZADO_ELEGIBILIDAD","Edad fuera del rango definido en catálogo",IF(K104="RECHAZADO_RUT_INVALIDO","RUT con formato o dígito verificador inválido","Prima informada no coincide con tarifa oficial PIMS")))))) -> Edad fuera del rango definido en catálogo | M104: =SUBSTITUTE(SUBSTITUTE(SUBSTITUTE(UPPER(TRIM(D104)),".",""),"-","")," ","") -> 243694981 | N104: =IF(OR(D104="",ISERROR(FIND("-",TRIM(D104))),MID(TRIM(D104),LEN(TRIM(D104))-1,1)<>"-",LEN(M104)<8,LEN(M104)>9,NOT(ISNUMBER(--LEFT(M104,LEN(M104)-1))),NOT(OR(RIGHT(M104,1)="K",IFERROR(ISNUMBER(--RIGHT(M104,1)),FALSE())))),"NO",IF(RIGHT(M104,1)=MID("0K987654321",MOD(SUMPRODUCT(--MID(RIGHT("00000000"&LEFT(M104,LEN(M104)-1),8),{1,2,3,4,5,6,7,8},1),{3,2,7,6,5,4,3,2}),11)+1,1),"SI","NO")) -> SI | O104: =IF(LEFT(K104,9)="RECHAZADO",COUNTIF($K$5:K104,"RECHAZADO*"),"") -> 38 | P104: =IF(OR(A104="",B104="",C104="",D104="",E104="",F104="",H104="",I104=""),"INCOMPLETO",IF(OR(NOT(ISNUMBER(B104)),NOT(ISNUMBER(F104)),F104>TODAY(),NOT(ISNUMBER(I104)),I104<0),"DATO_INVALIDO","OK")) -> OK | Q104: =IF(COUNTIF(Catalogo_Planes_PIMS!$B$5:$B$7,H104)=1,"SI","NO") -> SI | R104: =IF(A104="","",IF(COUNTIF($A$5:$A$104,A104)>1,"DUPLICADO","OK")) -> OK | S104: =IF(P104<>"OK","Revisar campos obligatorios, fechas y prima",IF(R104="DUPLICADO","ID_Solicitud duplicado",IF(Q104="NO","Plan no existe en catálogo",IF(AND(G104<>"",OR(G104<IFERROR(INDEX(Catalogo_Planes_PIMS!$D$5:$D$7,MATCH(H104,Catalogo_Planes_PIMS!$B$5:$B$7,0)),18),G104>IFERROR(INDEX(Catalogo_Planes_PIMS!$E$5:$E$7,MATCH(H104,Catalogo_Planes_PIMS!$B$5:$B$7,0)),65))),"Edad fuera de rango",IF(N104="NO","RUT inválido",IF(OR(J104="",I104<>J104),"Descalce de prima","Sin errores adicionales")))))) -> Edad fuera de rango

Sheet Catalogo_Planes_PIMS
A1: CATÁLOGO DE PLANES · TARIFA OFICIAL PIMS
A2: Matriz de referencia del sistema PIMS. Las pestañas Base y Dashboard consultan estos valores por fórmula.
A4: Codigo_Plan | B4: Nombre_Plan | C4: Prima_Oficial_CLP | D4: Edad_Minima | E4: Edad_Maxima | F4: Cobertura_Principal
A5: PLN-SAL-01 | B5: Seguro Salud Protegida | C5: 12990 | D5: 18 | E5: 65 | F5: Hospitalización, urgencias y cirugías por enfermedad o accidente
A6: PLN-VID-02 | B6: Seguro Vida Senior | C6: 18990 | D6: 18 | E6: 65 | F6: Fallecimiento por cualquier causa y gastos de sepelio
A7: PLN-HOG-03 | B7: Seguro Enseres Hogar | C7: 7990 | D7: 18 | E7: 65 | F7: Robo, incendio y daños por agua de los bienes del hogar
A9: Notas: (1) Prima mensual en pesos chilenos (valores simulados para el ejercicio). (2) El rango asegurable 18–65 años aplica a todos los planes, tal como define el caso; el nombre 'Vida Senior' es solo comercial. (3) Para cambiar una tarifa o un rango de edad, edite esta tabla: la validación de la Base se recalcula sola.

Sheet Dashboard_Cuadratura_Diaria
B1: DASHBOARD DE CUADRATURA DIARIA · SUSCRIPCIÓN MASIVOS Y CONTROL PIMS
B2: Jefatura de Suscripción y Socios Comerciales · Datos simulados · Fecha de corte (HOY): | H2: =TODAY() -> 46306
B4: TOTAL ALTAS RECIBIDAS | D4: TOTAL ALTAS APROBADAS | F4: TOTAL ALTAS RECHAZADAS | H4: TASA DE EFECTIVIDAD | J4: PRIMA TOTAL SUSCRITA APROBADA
B5: =COUNTA(Base_Altas_Recibidas!$A$5:$A$104) -> 100 | D5: =COUNTIF(Base_Altas_Recibidas!$K$5:$K$104,"APROBADO_CARGA_PIMS") -> 62 | F5: =COUNTIF(Base_Altas_Recibidas!$K$5:$K$104,"RECHAZADO*") -> 38 | H5: =IF(B5=0,0,D5/B5) -> 0.62 | J5: =SUMIFS(Base_Altas_Recibidas!$I$5:$I$104,Base_Altas_Recibidas!$K$5:$K$104,"APROBADO_CARGA_PIMS") -> 788380
B6: Solicitudes en la base | D6: Listas para cargar a PIMS | F6: Con observaciones | H6: Aprobadas ÷ Recibidas | J6: Suma de prima informada de aprobadas
B8: RESUMEN POR CANAL / SOCIO Y CAUSA RAÍZ DE RECHAZO
B9: Canal_Socio | C9: Total Recibidos | D9: Aprobados | E9: Rechazados Datos Incompletos | F9: Rechazados ID Duplicado | G9: Rechazados Plan No Catalogado | H9: Rechazados Elegibilidad | I9: Rechazados RUT Inválido | J9: Rechazados Descalce Prima | K9: Total Rechazados | L9: % Efectividad | M9: Prima Aprobada (CLP) | N9: % del Total Recibido
B10: CallCenter_Alpha | C10: =COUNTIF(Base_Altas_Recibidas!$C$5:$C$104,$B10) -> 43 | D10: =COUNTIFS(Base_Altas_Recibidas!$C$5:$C$104,$B10,Base_Altas_Recibidas!$K$5:$K$104,"APROBADO_CARGA_PIMS") -> 26 | E10: =COUNTIFS(Base_Altas_Recibidas!$C$5:$C$104,$B10,Base_Altas_Recibidas!$K$5:$K$104,"RECHAZADO_DATOS_INCOMPLETOS") -> 0 | F10: =COUNTIFS(Base_Altas_Recibidas!$C$5:$C$104,$B10,Base_Altas_Recibidas!$K$5:$K$104,"RECHAZADO_ID_DUPLICADO") -> 0 | G10: =COUNTIFS(Base_Altas_Recibidas!$C$5:$C$104,$B10,Base_Altas_Recibidas!$K$5:$K$104,"RECHAZADO_PLAN_NO_CATALOGADO") -> 0 | H10: =COUNTIFS(Base_Altas_Recibidas!$C$5:$C$104,$B10,Base_Altas_Recibidas!$K$5:$K$104,"RECHAZADO_ELEGIBILIDAD") -> 9 | I10: =COUNTIFS(Base_Altas_Recibidas!$C$5:$C$104,$B10,Base_Altas_Recibidas!$K$5:$K$104,"RECHAZADO_RUT_INVALIDO") -> 5 | J10: =COUNTIFS(Base_Altas_Recibidas!$C$5:$C$104,$B10,Base_Altas_Recibidas!$K$5:$K$104,"RECHAZADO_DESCALCE_PRIMA") -> 3 | K10: =SUM(E10:J10) -> 17 | L10: =IF(C10=0,0,D10/C10) -> 0.60465116 | M10: =SUMIFS(Base_Altas_Recibidas!$I$5:$I$104,Base_Altas_Recibidas!$C$5:$C$104,$B10,Base_Altas_Recibidas!$K$5:$K$104,"APROBADO_CARGA_PIMS") -> 335740 | N10: =IF($C$13=0,0,C10/$C$13) -> 0.43
B11: CallCenter_Beta | C11: =COUNTIF(Base_Altas_Recibidas!$C$5:$C$104,$B11) -> 30 | D11: =COUNTIFS(Base_Altas_Recibidas!$C$5:$C$104,$B11,Base_Altas_Recibidas!$K$5:$K$104,"APROBADO_CARGA_PIMS") -> 19 | E11: =COUNTIFS(Base_Altas_Recibidas!$C$5:$C$104,$B11,Base_Altas_Recibidas!$K$5:$K$104,"RECHAZADO_DATOS_INCOMPLETOS") -> 0 | F11: =COUNTIFS(Base_Altas_Recibidas!$C$5:$C$104,$B11,Base_Altas_Recibidas!$K$5:$K$104,"RECHAZADO_ID_DUPLICADO") -> 0 | G11: =COUNTIFS(Base_Altas_Recibidas!$C$5:$C$104,$B11,Base_Altas_Recibidas!$K$5:$K$104,"RECHAZADO_PLAN_NO_CATALOGADO") -> 0 | H11: =COUNTIFS(Base_Altas_Recibidas!$C$5:$C$104,$B11,Base_Altas_Recibidas!$K$5:$K$104,"RECHAZADO_ELEGIBILIDAD") -> 4 | I11: =COUNTIFS(Base_Altas_Recibidas!$C$5:$C$104,$B11,Base_Altas_Recibidas!$K$5:$K$104,"RECHAZADO_RUT_INVALIDO") -> 2 | J11: =COUNTIFS(Base_Altas_Recibidas!$C$5:$C$104,$B11,Base_Altas_Recibidas!$K$5:$K$104,"RECHAZADO_DESCALCE_PRIMA") -> 5 | K11: =SUM(E11:J11) -> 11 | L11: =IF(C11=0,0,D11/C11) -> 0.63333333 | M11: =SUMIFS(Base_Altas_Recibidas!$I$5:$I$104,Base_Altas_Recibidas!$C$5:$C$104,$B11,Base_Altas_Recibidas!$K$5:$K$104,"APROBADO_CARGA_PIMS") -> 243810 | N11: =IF($C$13=0,0,C11/$C$13) -> 0.3
B12: Socio_Retail_Gamma | C12: =COUNTIF(Base_Altas_Recibidas!$C$5:$C$104,$B12) -> 27 | D12: =COUNTIFS(Base_Altas_Recibidas!$C$5:$C$104,$B12,Base_Altas_Recibidas!$K$5:$K$104,"APROBADO_CARGA_PIMS") -> 17 | E12: =COUNTIFS(Base_Altas_Recibidas!$C$5:$C$104,$B12,Base_Altas_Recibidas!$K$5:$K$104,"RECHAZADO_DATOS_INCOMPLETOS") -> 0 | F12: =COUNTIFS(Base_Altas_Recibidas!$C$5:$C$104,$B12,Base_Altas_Recibidas!$K$5:$K$104,"RECHAZADO_ID_DUPLICADO") -> 0 | G12: =COUNTIFS(Base_Altas_Recibidas!$C$5:$C$104,$B12,Base_Altas_Recibidas!$K$5:$K$104,"RECHAZADO_PLAN_NO_CATALOGADO") -> 0 | H12: =COUNTIFS(Base_Altas_Recibidas!$C$5:$C$104,$B12,Base_Altas_Recibidas!$K$5:$K$104,"RECHAZADO_ELEGIBILIDAD") -> 4 | I12: =COUNTIFS(Base_Altas_Recibidas!$C$5:$C$104,$B12,Base_Altas_Recibidas!$K$5:$K$104,"RECHAZADO_RUT_INVALIDO") -> 4 | J12: =COUNTIFS(Base_Altas_Recibidas!$C$5:$C$104,$B12,Base_Altas_Recibidas!$K$5:$K$104,"RECHAZADO_DESCALCE_PRIMA") -> 2 | K12: =SUM(E12:J12) -> 10 | L12: =IF(C12=0,0,D12/C12) -> 0.62962963 | M12: =SUMIFS(Base_Altas_Recibidas!$I$5:$I$104,Base_Altas_Recibidas!$C$5:$C$104,$B12,Base_Altas_Recibidas!$K$5:$K$104,"APROBADO_CARGA_PIMS") -> 208830 | N12: =IF($C$13=0,0,C12/$C$13) -> 0.27
B13: TOTAL | C13: =SUM(C10:C12) -> 100 | D13: =SUM(D10:D12) -> 62 | E13: =SUM(E10:E12) -> 0 | F13: =SUM(F10:F12) -> 0 | G13: =SUM(G10:G12) -> 0 | H13: =SUM(H10:H12) -> 17 | I13: =SUM(I10:I12) -> 11 | J13: =SUM(J10:J12) -> 10 | K13: =SUM(K10:K12) -> 38 | L13: =IF(C13=0,0,D13/C13) -> 0.62 | M13: =SUM(M10:M12) -> 788380 | N13: =SUM(N10:N12) -> 1
B14: Control de cuadratura: Aprobados + Rechazados = Total Recibido (tabla) = Total en base | H14: =IF(AND(D13+K13=C13,C13=B5,D13=D5,K13=F5),"CUADRA OK","REVISAR") -> CUADRA OK
B35: Prioridad de reglas: 1) Datos obligatorios y fechas/prima válidas · 2) ID duplicado · 3) Plan existente en catálogo · 4) Elegibilidad según catálogo · 5) RUT válido por módulo 11 · 6) Cuadratura de prima. Cada solicitud se clasifica por la primera causa que falla; los errores adicionales se conservan en Base_Altas_Recibidas para revisión. Los datos y las reglas son simulados y deben validarse contra condiciones reales del producto.

Sheet Auditoria_Rechazos_PIMS
A1: REPORTE DE HALLAZGOS Y AUDITORÍA DE SUSCRIPCIÓN · SISTEMA PIMS
A2: Altas que no superaron los controles de calidad. Reporte dinámico alimentado desde la base; cada solicitud aparece una sola vez con su causa principal.
B4: TOTAL REGISTROS AUDITADOS | D4: RECHAZOS POR ELEGIBILIDAD | F4: RECHAZOS POR RUT INVÁLIDO | G4: RECHAZOS POR DESCALCE DE PRIMA | H4: CONTROL DE CUADRATURA | J4: OTRAS CAUSAS DE RECHAZO
B5: =COUNTIF(Base_Altas_Recibidas!$K$5:$K$104,"RECHAZADO*") -> 38 | D5: =COUNTIF(Base_Altas_Recibidas!$K$5:$K$104,"RECHAZADO_ELEGIBILIDAD") -> 17 | F5: =COUNTIF(Base_Altas_Recibidas!$K$5:$K$104,"RECHAZADO_RUT_INVALIDO") -> 11 | G5: =COUNTIF(Base_Altas_Recibidas!$K$5:$K$104,"RECHAZADO_DESCALCE_PRIMA") -> 10 | H5: =IF(AND(D5+F5+G5+J5=B5,COUNT($A$9:$A$108)=B5,B5=Dashboard_Cuadratura_Diaria!$F$5),"CUADRA OK","REVISAR") -> CUADRA OK | J5: =COUNTIF(Base_Altas_Recibidas!$K$5:$K$104,"RECHAZADO_DATOS_INCOMPLETOS")+COUNTIF(Base_Altas_Recibidas!$K$5:$K$104,"RECHAZADO_ID_DUPLICADO")+COUNTIF(Base_Altas_Recibidas!$K$5:$K$104,"RECHAZADO_PLAN_NO_CATALOGADO") -> 0
B6: Altas rechazadas en la base | D6: Edad fuera de 18-65 años | F6: Formato o dígito verificador M11 | G6: Prima distinta a la tarifa oficial | H6: Suma de causas = total = Dashboard | J6: Datos incompletos, ID duplicado o plan inexistente
A7: DETALLE DE EXCEPCIONES POR REGISTRO RECHAZADO
A8: N° | B8: ID_Solicitud | C8: Canal_Socio | D8: RUT_Asegurado | E8: Nombre_Asegurado | F8: Causa_Raiz | G8: Detalle_Tecnico_Hallazgo | H8: Accion_Requerida_Socio | I8: Fila_Base (aux)
A9: N° | B9: ID_Solicitud | C9: Canal_Socio | D9: RUT_Asegurado | E9: Nombre_Asegurado | F9: Causa_Raiz | G9: Detalle_Tecnico_Hallazgo | H9: Accion_Requerida_Socio | I9: Fila_Base (aux)
A10: =IF(ROWS($A$10:$A10)<=$B$5,ROWS($A$10:$A10),"") -> 1 | B10: =IF($A10="","",INDEX(Base_Altas_Recibidas!$A$5:$A$104,$I10)) -> SEC-1003 | C10: =IF($A10="","",INDEX(Base_Altas_Recibidas!$C$5:$C$104,$I10)) -> Socio_Retail_Gamma | D10: =IF($A10="","",INDEX(Base_Altas_Recibidas!$D$5:$D$104,$I10)) -> 21.104.204-4 | E10: =IF($A10="","",INDEX(Base_Altas_Recibidas!$E$5:$E$104,$I10)) -> Tomás Hernández Espinoza | F10: =IF($A10="","",INDEX(Base_Altas_Recibidas!$K$5:$K$104,$I10)) -> RECHAZADO_DESCALCE_PRIMA | G10: =IF($A10="","",IF($F10="RECHAZADO_DATOS_INCOMPLETOS","Campos obligatorios incompletos o fecha/prima inválida",IF($F10="RECHAZADO_ID_DUPLICADO","Identificador de solicitud duplicado: "&$B10,IF($F10="RECHAZADO_PLAN_NO_CATALOGADO","El plan solicitado no existe en el catálogo PIMS: "&INDEX(Base_Altas_Recibidas!$H$5:$H$104,$I10),IF($F10="RECHAZADO_ELEGIBILIDAD","Edad fuera del rango definido en catálogo (18-65 como supuesto del laboratorio): "&INDEX(Base_Altas_Recibidas!$G$5:$G$104,$I10)&" años",IF($F10="RECHAZADO_RUT_INVALIDO",IF(OR(NOT(ISNUMBER(FIND("-",TRIM($D10)))),LEN(INDEX(Base_Altas_Recibidas!$M$5:$M$104,$I10))<8,LEN(INDEX(Base_Altas_Recibidas!$M$5:$M$104,$I10))>9),"Formato de RUT incompleto o inválido","Dígito verificador Módulo 11 no coincide"),"Prima informada ($"&INDEX(Base_Altas_Recibidas!$I$5:$I$104,$I10)&") no coincide con tarifa oficial PIMS ($"&INDEX(Base_Altas_Recibidas!$J$5:$J$104,$I10)&")")))))) -> Prima informada ($17990) no coincide con tarifa oficial PIMS ($18990) | H10: =IF($A10="","",IF($F10="RECHAZADO_DATOS_INCOMPLETOS","Completar/corregir los campos de entrada y volver a validar.",IF($F10="RECHAZADO_ID_DUPLICADO","Verificar el ID y asignar un identificador único antes de reenviar.",IF($F10="RECHAZADO_PLAN_NO_CATALOGADO","Confirmar el código/nombre del producto con Suscripción antes de reenviar.",IF($F10="RECHAZADO_ELEGIBILIDAD","No cargar; confirmar elegibilidad según condiciones autorizadas del producto.",IF($F10="RECHAZADO_RUT_INVALIDO","Contrastar con documento de identidad, corregir RUT y volver a validar.","Corregir prima contra el catálogo oficial; si hubo cobro distinto, escalar para regularización.")))))) -> Corregir prima contra el catálogo oficial; si hubo cobro distinto, escalar para regularización. | I10: =IF($A10="","",MATCH($A10,Base_Altas_Recibidas!$O$5:$O$104,0)) -> 3
A11: =IF(ROWS($A$10:$A11)<=$B$5,ROWS($A$10:$A11),"") -> 2 | B11: =IF($A11="","",INDEX(Base_Altas_Recibidas!$A$5:$A$104,$I11)) -> SEC-1004 | C11: =IF($A11="","",INDEX(Base_Altas_Recibidas!$C$5:$C$104,$I11)) -> CallCenter_Alpha | D11: =IF($A11="","",INDEX(Base_Altas_Recibidas!$D$5:$D$104,$I11)) -> 23.435.343-8 | E11: =IF($A11="","",INDEX(Base_Altas_Recibidas!$E$5:$E$104,$I11)) -> Rodrigo Morales Hernández | F11: =IF($A11="","",INDEX(Base_Altas_Recibidas!$K$5:$K$104,$I11)) -> RECHAZADO_ELEGIBILIDAD | G11: =IF($A11="","",IF($F11="RECHAZADO_DATOS_INCOMPLETOS","Campos obligatorios incompletos o fecha/prima inválida",IF($F11="RECHAZADO_ID_DUPLICADO","Identificador de solicitud duplicado: "&$B11,IF($F11="RECHAZADO_PLAN_NO_CATALOGADO","El plan solicitado no existe en el catálogo PIMS: "&INDEX(Base_Altas_Recibidas!$H$5:$H$104,$I11),IF($F11="RECHAZADO_ELEGIBILIDAD","Edad fuera del rango definido en catálogo (18-65 como supuesto del laboratorio): "&INDEX(Base_Altas_Recibidas!$G$5:$G$104,$I11)&" años",IF($F11="RECHAZADO_RUT_INVALIDO",IF(OR(NOT(ISNUMBER(FIND("-",TRIM($D11)))),LEN(INDEX(Base_Altas_Recibidas!$M$5:$M$104,$I11))<8,LEN(INDEX(Base_Altas_Recibidas!$M$5:$M$104,$I11))>9),"Formato de RUT incompleto o inválido","Dígito verificador Módulo 11 no coincide"),"Prima informada ($"&INDEX(Base_Altas_Recibidas!$I$5:$I$104,$I11)&") no coincide con tarifa oficial PIMS ($"&INDEX(Base_Altas_Recibidas!$J$5:$J$104,$I11)&")")))))) -> Edad fuera del rango definido en catálogo (18-65 como supuesto del laboratorio): 13 años | H11: =IF($A11="","",IF($F11="RECHAZADO_DATOS_INCOMPLETOS","Completar/corregir los campos de entrada y volver a validar.",IF($F11="RECHAZADO_ID_DUPLICADO","Verificar el ID y asignar un identificador único antes de reenviar.",IF($F11="RECHAZADO_PLAN_NO_CATALOGADO","Confirmar el código/nombre del producto con Suscripción antes de reenviar.",IF($F11="RECHAZADO_ELEGIBILIDAD","No cargar; confirmar elegibilidad según condiciones autorizadas del producto.",IF($F11="RECHAZADO_RUT_INVALIDO","Contrastar con documento de identidad, corregir RUT y volver a validar.","Corregir prima contra el catálogo oficial; si hubo cobro distinto, escalar para regularización.")))))) -> No cargar; confirmar elegibilidad según condiciones autorizadas del producto. | I11: =IF($A11="","",MATCH($A11,Base_Altas_Recibidas!$O$5:$O$104,0)) -> 4
A12: =IF(ROWS($A$10:$A12)<=$B$5,ROWS($A$10:$A12),"") -> 3 | B12: =IF($A12="","",INDEX(Base_Altas_Recibidas!$A$5:$A$104,$I12)) -> SEC-1008 | C12: =IF($A12="","",INDEX(Base_Altas_Recibidas!$C$5:$C$104,$I12)) -> CallCenter_Beta | D12: =IF($A12="","",INDEX(Base_Altas_Recibidas!$D$5:$D$104,$I12)) -> 15.153.880-0 | E12: =IF($A12="","",INDEX(Base_Altas_Recibidas!$E$5:$E$104,$I12)) -> Valentina López Sepúlveda | F12: =IF($A12="","",INDEX(Base_Altas_Recibidas!$K$5:$K$104,$I12)) -> RECHAZADO_DESCALCE_PRIMA | G12: =IF($A12="","",IF($F12="RECHAZADO_DATOS_INCOMPLETOS","Campos obligatorios incompletos o fecha/prima inválida",IF($F12="RECHAZADO_ID_DUPLICADO","Identificador de solicitud duplicado: "&$B12,IF($F12="RECHAZADO_PLAN_NO_CATALOGADO","El plan solicitado no existe en el catálogo PIMS: "&INDEX(Base_Altas_Recibidas!$H$5:$H$104,$I12),IF($F12="RECHAZADO_ELEGIBILIDAD","Edad fuera del rango definido en catálogo (18-65 como supuesto del laboratorio): "&INDEX(Base_Altas_Recibidas!$G$5:$G$104,$I12)&" años",IF($F12="RECHAZADO_RUT_INVALIDO",IF(OR(NOT(ISNUMBER(FIND("-",TRIM($D12)))),LEN(INDEX(Base_Altas_Recibidas!$M$5:$M$104,$I12))<8,LEN(INDEX(Base_Altas_Recibidas!$M$5:$M$104,$I12))>9),"Formato de RUT incompleto o inválido","Dígito verificador Módulo 11 no coincide"),"Prima informada ($"&INDEX(Base_Altas_Recibidas!$I$5:$I$104,$I12)&") no coincide con tarifa oficial PIMS ($"&INDEX(Base_Altas_Recibidas!$J$5:$J$104,$I12)&")")))))) -> Prima informada ($9490) no coincide con tarifa oficial PIMS ($7990) | H12: =IF($A12="","",IF($F12="RECHAZADO_DATOS_INCOMPLETOS","Completar/corregir los campos de entrada y volver a validar.",IF($F12="RECHAZADO_ID_DUPLICADO","Verificar el ID y asignar un identificador único antes de reenviar.",IF($F12="RECHAZADO_PLAN_NO_CATALOGADO","Confirmar el código/nombre del producto con Suscripción antes de reenviar.",IF($F12="RECHAZADO_ELEGIBILIDAD","No cargar; confirmar elegibilidad según condiciones autorizadas del producto.",IF($F12="RECHAZADO_RUT_INVALIDO","Contrastar con documento de identidad, corregir RUT y volver a validar.","Corregir prima contra el catálogo oficial; si hubo cobro distinto, escalar para regularización.")))))) -> Corregir prima contra el catálogo oficial; si hubo cobro distinto, escalar para regularización. | I12: =IF($A12="","",MATCH($A12,Base_Altas_Recibidas!$O$5:$O$104,0)) -> 8
A13: =IF(ROWS($A$10:$A13)<=$B$5,ROWS($A$10:$A13),"") -> 4 | B13: =IF($A13="","",INDEX(Base_Altas_Recibidas!$A$5:$A$104,$I13)) -> SEC-1009 | C13: =IF($A13="","",INDEX(Base_Altas_Recibidas!$C$5:$C$104,$I13)) -> CallCenter_Beta | D13: =IF($A13="","",INDEX(Base_Altas_Recibidas!$D$5:$D$104,$I13)) -> 14.839.703-1 | E13: =IF($A13="","",INDEX(Base_Altas_Recibidas!$E$5:$E$104,$I13)) -> Ignacio Sepúlveda Hernández | F13: =IF($A13="","",INDEX(Base_Altas_Recibidas!$K$5:$K$104,$I13)) -> RECHAZADO_DESCALCE_PRIMA | G13: =IF($A13="","",IF($F13="RECHAZADO_DATOS_INCOMPLETOS","Campos obligatorios incompletos o fecha/prima inválida",IF($F13="RECHAZADO_ID_DUPLICADO","Identificador de solicitud duplicado: "&$B13,IF($F13="RECHAZADO_PLAN_NO_CATALOGADO","El plan solicitado no existe en el catálogo PIMS: "&INDEX(Base_Altas_Recibidas!$H$5:$H$104,$I13),IF($F13="RECHAZADO_ELEGIBILIDAD","Edad fuera del rango definido en catálogo (18-65 como supuesto del laboratorio): "&INDEX(Base_Altas_Recibidas!$G$5:$G$104,$I13)&" años",IF($F13="RECHAZADO_RUT_INVALIDO",IF(OR(NOT(ISNUMBER(FIND("-",TRIM($D13)))),LEN(INDEX(Base_Altas_Recibidas!$M$5:$M$104,$I13))<8,LEN(INDEX(Base_Altas_Recibidas!$M$5:$M$104,$I13))>9),"Formato de RUT incompleto o inválido","Dígito verificador Módulo 11 no coincide"),"Prima informada ($"&INDEX(Base_Altas_Recibidas!$I$5:$I$104,$I13)&") no coincide con tarifa oficial PIMS ($"&INDEX(Base_Altas_Recibidas!$J$5:$J$104,$I13)&")")))))) -> Prima informada ($14490) no coincide con tarifa oficial PIMS ($12990) | H13: =IF($A13="","",IF($F13="RECHAZADO_DATOS_INCOMPLETOS","Completar/corregir los campos de entrada y volver a validar.",IF($F13="RECHAZADO_ID_DUPLICADO","Verificar el ID y asignar un identificador único antes de reenviar.",IF($F13="RECHAZADO_PLAN_NO_CATALOGADO","Confirmar el código/nombre del producto con Suscripción antes de reenviar.",IF($F13="RECHAZADO_ELEGIBILIDAD","No cargar; confirmar elegibilidad según condiciones autorizadas del producto.",IF($F13="RECHAZADO_RUT_INVALIDO","Contrastar con documento de identidad, corregir RUT y volver a validar.","Corregir prima contra el catálogo oficial; si hubo cobro distinto, escalar para regularización.")))))) -> Corregir prima contra el catálogo oficial; si hubo cobro distinto, escalar para regularización. | I13: =IF($A13="","",MATCH($A13,Base_Altas_Recibidas!$O$5:$O$104,0)) -> 9
A14: =IF(ROWS($A$10:$A14)<=$B$5,ROWS($A$10:$A14),"") -> 5 | B14: =IF($A14="","",INDEX(Base_Altas_Recibidas!$A$5:$A$104,$I14)) -> SEC-1011 | C14: =IF($A14="","",INDEX(Base_Altas_Recibidas!$C$5:$C$104,$I14)) -> Socio_Retail_Gamma | D14: =IF($A14="","",INDEX(Base_Altas_Recibidas!$D$5:$D$104,$I14)) -> 6.164.612-7 | E14: =IF($A14="","",INDEX(Base_Altas_Recibidas!$E$5:$E$104,$I14)) -> Macarena Morales Fuentes | F14: =IF($A14="","",INDEX(Base_Altas_Recibidas!$K$5:$K$104,$I14)) -> RECHAZADO_RUT_INVALIDO | G14: =IF($A14="","",IF($F14="RECHAZADO_DATOS_INCOMPLETOS","Campos obligatorios incompletos o fecha/prima inválida",IF($F14="RECHAZADO_ID_DUPLICADO","Identificador de solicitud duplicado: "&$B14,IF($F14="RECHAZADO_PLAN_NO_CATALOGADO","El plan solicitado no existe en el catálogo PIMS: "&INDEX(Base_Altas_Recibidas!$H$5:$H$104,$I14),IF($F14="RECHAZADO_ELEGIBILIDAD","Edad fuera del rango definido en catálogo (18-65 como supuesto del laboratorio): "&INDEX(Base_Altas_Recibidas!$G$5:$G$104,$I14)&" años",IF($F14="RECHAZADO_RUT_INVALIDO",IF(OR(NOT(ISNUMBER(FIND("-",TRIM($D14)))),LEN(INDEX(Base_Altas_Recibidas!$M$5:$M$104,$I14))<8,LEN(INDEX(Base_Altas_Recibidas!$M$5:$M$104,$I14))>9),"Formato de RUT incompleto o inválido","Dígito verificador Módulo 11 no coincide"),"Prima informada ($"&INDEX(Base_Altas_Recibidas!$I$5:$I$104,$I14)&") no coincide con tarifa oficial PIMS ($"&INDEX(Base_Altas_Recibidas!$J$5:$J$104,$I14)&")")))))) -> Dígito verificador Módulo 11 no coincide | H14: =IF($A14="","",IF($F14="RECHAZADO_DATOS_INCOMPLETOS","Completar/corregir los campos de entrada y volver a validar.",IF($F14="RECHAZADO_ID_DUPLICADO","Verificar el ID y asignar un identificador único antes de reenviar.",IF($F14="RECHAZADO_PLAN_NO_CATALOGADO","Confirmar el código/nombre del producto con Suscripción antes de reenviar.",IF($F14="RECHAZADO_ELEGIBILIDAD","No cargar; confirmar elegibilidad según condiciones autorizadas del producto.",IF($F14="RECHAZADO_RUT_INVALIDO","Contrastar con documento de identidad, corregir RUT y volver a validar.","Corregir prima contra el catálogo oficial; si hubo cobro distinto, escalar para regularización.")))))) -> Contrastar con documento de identidad, corregir RUT y volver a validar. | I14: =IF($A14="","",MATCH($A14,Base_Altas_Recibidas!$O$5:$O$104,0)) -> 11
A15: =IF(ROWS($A$10:$A15)<=$B$5,ROWS($A$10:$A15),"") -> 6 | B15: =IF($A15="","",INDEX(Base_Altas_Recibidas!$A$5:$A$104,$I15)) -> SEC-1014 | C15: =IF($A15="","",INDEX(Base_Altas_Recibidas!$C$5:$C$104,$I15)) -> CallCenter_Beta | D15: =IF($A15="","",INDEX(Base_Altas_Recibidas!$D$5:$D$104,$I15)) -> 14.995.966-1 | E15: =IF($A15="","",INDEX(Base_Altas_Recibidas!$E$5:$E$104,$I15)) -> Francisca Díaz Martínez | F15: =IF($A15="","",INDEX(Base_Altas_Recibidas!$K$5:$K$104,$I15)) -> RECHAZADO_ELEGIBILIDAD | G15: =IF($A15="","",IF($F15="RECHAZADO_DATOS_INCOMPLETOS","Campos obligatorios incompletos o fecha/prima inválida",IF($F15="RECHAZADO_ID_DUPLICADO","Identificador de solicitud duplicado: "&$B15,IF($F15="RECHAZADO_PLAN_NO_CATALOGADO","El plan solicitado no existe en el catálogo PIMS: "&INDEX(Base_Altas_Recibidas!$H$5:$H$104,$I15),IF($F15="RECHAZADO_ELEGIBILIDAD","Edad fuera del rango definido en catálogo (18-65 como supuesto del laboratorio): "&INDEX(Base_Altas_Recibidas!$G$5:$G$104,$I15)&" años",IF($F15="RECHAZADO_RUT_INVALIDO",IF(OR(NOT(ISNUMBER(FIND("-",TRIM($D15)))),LEN(INDEX(Base_Altas_Recibidas!$M$5:$M$104,$I15))<8,LEN(INDEX(Base_Altas_Recibidas!$M$5:$M$104,$I15))>9),"Formato de RUT incompleto o inválido","Dígito verificador Módulo 11 no coincide"),"Prima informada ($"&INDEX(Base_Altas_Recibidas!$I$5:$I$104,$I15)&") no coincide con tarifa oficial PIMS ($"&INDEX(Base_Altas_Recibidas!$J$5:$J$104,$I15)&")")))))) -> Edad fuera del rango definido en catálogo (18-65 como supuesto del laboratorio): 13 años | H15: =IF($A15="","",IF($F15="RECHAZADO_DATOS_INCOMPLETOS","Completar/corregir los campos de entrada y volver a validar.",IF($F15="RECHAZADO_ID_DUPLICADO","Verificar el ID y asignar un identificador único antes de reenviar.",IF($F15="RECHAZADO_PLAN_NO_CATALOGADO","Confirmar el código/nombre del producto con Suscripción antes de reenviar.",IF($F15="RECHAZADO_ELEGIBILIDAD","No cargar; confirmar elegibilidad según condiciones autorizadas del producto.",IF($F15="RECHAZADO_RUT_INVALIDO","Contrastar con documento de identidad, corregir RUT y volver a validar.","Corregir prima contra el catálogo oficial; si hubo cobro distinto, escalar para regularización.")))))) -> No cargar; confirmar elegibilidad según condiciones autorizadas del producto. | I15: =IF($A15="","",MATCH($A15,Base_Altas_Recibidas!$O$5:$O$104,0)) -> 14
